2024.05.07
현재 발생중인 오류

$ "C:/Users/Do yun/AppData/Local/Programs/Python/Python310/python.exe" "c:/Users/Do yun/Desktop/Project/test.py"
c:\Users\Do yun\Desktop\Project\test.py:90: FutureWarning: In a future version of pandas all arguments of DataFrame.pivot will be keyword-only.
  df.pivot('keys', 'octave', 'hertz')
{440: 'A_4', 466.16: 'Bb_4', 493.88: 'B_4', 523.25: 'C_5', 554.37: 'C#_5', 587.33: 'D_5', 622.25: 'D#_5', 659.26: 'E_5', 698.46: 'F_5', 739.99: 'F#_5', 783.99: 'G_5', 830.61: 'G#_5', 880.0: 'A_5', 932.33: 'Bb_5', 987.77: 'B_5', 1046.5: 'C_6', 1108.73: 'C#_6', 1174.66: 'D_6', 1244.51: 'D#_6', 1318.51: 'E_6', 1396.91: 'F_6', 1479.98: 'F#_6', 1567.98: 'G_6', 1661.22: 'G#_6', 1760.0: 'A_6', 1864.66: 'Bb_6', 1975.53: 'B_6', 2093.0: 'C_7', 2217.46: 'C#_7', 2349.32: 'D_7', 2489.02: 'D#_7', 2637.02: 'E_7', 2793.83: 'F_7', 2959.96: 'F#_7', 3135.96: 'G_7', 3322.44: 'G#_7', 3520.0: 'A_7', 3729.31: 'Bb_7', 3951.07: 'B_7', 4186.01: 'C_8', 4434.92: 'C#_8', 4698.64: 'D_8', 4978.03: 'D#_8', 5274.04: 'E_8', 5587.65: 'F_8', 5919.91: 'F#_8', 6271.93: 'G_8', 6644.88: 'G#_8', 7040.0: 'A_8', 7458.62: 'Bb_8', 7902.13: 'B_8', 415.3: 'G#_4', 392.0: 'G_4', 369.99: 'F#_4', 349.23: 'F_4', 329.63: 'E_4', 311.13: 'D#_4', 293.66: 'D_4', 277.18: 'C#_4', 261.63: 'C_4', 246.94: 'B_3', 233.08: 'Bb_3', 220.0: 'A_3', 207.65: 'G#_3', 196.0: 'G_3', 185.0: 'F#_3', 174.61: 'F_3', 164.81: 'E_3', 155.56: 'D#_3', 146.83: 'D_3', 138.59: 'C#_3', 130.81: 'C_3', 123.47: 'B_2', 116.54: 'Bb_2', 110.0: 'A_2', 103.83: 'G#_2', 98.0: 'G_2', 92.5: 'F#_2', 87.31: 'F_2', 82.41: 'E_2', 77.78: 'D#_2', 73.42: 'D_2', 69.3: 'C#_2', 65.41: 'C_2', 61.74: 'B_1', 58.27: 'Bb_1', 55.0: 'A_1', 51.91: 'G#_1', 49.0: 'G_1', 46.25: 'F#_1', 43.65: 'F_1', 41.2: 'E_1', 38.89: 'D#_1', 36.71: 'D_1', 34.65: 'C#_1', 32.7: 'C_1', 30.87: 'B_0', 29.14: 'Bb_0', 27.5: 'A_0', 25.96: 'G#_0', 24.5: 'G_0', 23.12: 'F#_0', 21.83: 'F_0', 20.6: 'E_0', 19.45: 'D#_0', 18.35: 'D_0', 17.32: 'C#_0', 16.35: 'C_0'}
Traceback (most recent call last):
  File "c:\Users\Do yun\Desktop\Project\test.py", line 188, in <module>
    print(hertz2keys['Bb_6'])
KeyError: 'Bb_6'
